Workbook
Name _2_2_2: #REF!
Name _2_X_2_X_2.8Bondor: #REF!
Name _2_X_2_X_2.8Dawamiba: #REF!
Name _2_X_2_X_2.8Pangaji: #REF!
Name _3_X_4.2_X_2.85__Backbone_Bondor: #REF!
Name _3_X_4.2_X_2.85__Backbone_Dawamiba: #REF!
Name _3_X_4.2_X_2.85__Backbone_Pangaji: #REF!
Name _6_X_12_X_3.2Bondor: #REF!
Name _6_X_12_X_3.2Dawamiba: #REF!
Name _6_X_12_X_3.2Pangaji: #REF!
Name _750_KVA_X_64__: #REF!
Name _AAD3: HAJIME:OWARI
Name _AAD3: [0]!HAJIME:[0]!OWARI
Name _AAD3: [0]!HAJIME:[0]!OWARI
Name _AAD3: [0]!HAJIME:[0]!OWARI
Name _AAD3: [0]!HAJIME:[0]!OWARI
Name _AAD3: [0]!HAJIME:[0]!OWARI
Name _AAD3: HAJIME:OWARI
Name _ADD1: STOP2:STOP2E
Name _ADD1: [0]!STOP2:[0]!STOP2E
Name _ADD1: [0]!STOP2:[0]!STOP2E
Name _ADD1: [0]!STOP2:[0]!STOP2E
Name _ADD1: [0]!STOP2:[0]!STOP2E
Name _ADD1: [0]!STOP2:[0]!STOP2E
Name _ADD1: STOP2:STOP2E
Name _ADD2: STOP:STOPE
Name _ADD2: [0]!STOP:[0]!STOPE
Name _ADD2: [0]!STOP:[0]!STOPE
Name _ADD2: [0]!STOP:[0]!STOPE
Name _ADD2: [0]!STOP:[0]!STOPE
Name _ADD2: [0]!STOP:[0]!STOPE
Name _ADD2: STOP:STOPE
Name _ADD3: STOP:STOPE
Name _ADD3: [0]!STOP:[0]!STOPE
Name _ADD3: [0]!STOP:[0]!STOPE
Name _ADD3: [0]!STOP:[0]!STOPE
Name _ADD3: [0]!STOP:[0]!STOPE
Name _ADD3: [0]!STOP:[0]!STOPE
Name _ADD3: STOP:STOPE
Name _BOX2: #REF!
Name _BOX2: #REF!
Name _BOX2: #REF!
Name _BOX2: #REF!
Name _BOX2: #REF!
Name _BOX2: #REF!
Name _BOX2: #REF!
Name _CAL1: #REF!
Name _CAL1: #REF!
Name _CAL1: #REF!
Name _CAL1: #REF!
Name _CAL1: #REF!
Name _CAL1: #REF!
Name _CAL1: #REF!
Name _CAL10: #REF!
Name _CAL11: #REF!
Name _CAL12: #REF!
Name _CAL13: #REF!
Name _CAL14: #REF!
Name _CAL15: #REF!
Name _CAL16: #REF!

Sheet Stacking Shelter Checklist
F1: CO-LOCATION SITE ACCEPTANCE | R1: Contractor Logo
F2: Site ID: | L2: Submit Date:
F3: Site Name: | L3: Project:
A5: APPLICABLE FOR STACKING SHELTER WORK
A6: SITE INFORMATION
A8: Site ID | G8: :
A9: Site Name | G9: :
A10: Site Address | G10: :
A11: Installed By | G11: :
A12: Material Supplied By | G12: :
A13: Tower Upgrade Type | G13: :
A14: Inspection Date | G14: :
A15: Carrier | G15: :
A16: RFI Date as per Colo Tracker | G16: :
A18: INSPECTION CHECK LIST
A20: NO | C20: INSPECTION ITEM | M20: ACCEPTANCE | P20: CRITERIA | U20: REMARKS
M21: YES | N21: NO | O21: N/A
A22: 1 | C22: FOUNDATION (CIVIL WORKS)
B23: a | C23: Type of foundation
B24: b | C24: Dimension
C25: - Base | P25: Conform
C26: - Column | P26: Conform
C27: - Depth | P27: Conform
B28: c | C28: Concrete
C29: - Concrete Strength Certificate | P29: Provided / Within the specification
C30: - Concrete Surface | P30: Good
B31: d | C31: Anchor
C32: - Diameter | P32: Conform
C33: - Grouting | P33: Good / Smooth / Done
C34: - Placement | P34: Firmly fixed / Conform
C35: - Level | P35: Good / Level / Conform
B36: e | C36: Finishing Works
C37: - Soil Compacting | P37: Done / Neat / Conform
C38: - Site Cleaning | P38: Clean / Neat
A39: 2 | C39: STEEL STRUCTURE
B40: a | C40: Steel material
C41: - Wide Flange (H-Beam and I-Beam) and Angle Steel | P41: Mill Certificate provided / Within the specification / Complete and Conform to design / Not Bend or Camber / Galvanized
C42: - Bolt, Nut, Plate Washer and Spring Washer | P42: Tightened within torque spec / Complete / Galvanized / HTB
C43: - Chequered Plate | P43: Conform / Galvanized
B44: b | C44: Installation | P44: Conform / All member properly connected and installed
...

Sheet QC Point and Checklist
A1: QC Point and Checklist
A3: No | B3: Inspection Point | C3: No | D3: Item Description | E3: Value | F3: Inspection result | G3: Point | H3: Total Point | I3: Point in words
A4: 1 | B4: Material Supply | C4: a | D4: Profile material | E4: =100/2 -> 50 | F4: 1 | G4: =E4*F4 -> 50 | H4: =SUM(G4:G5) -> 100 | I4: =IF(H4>66.67,"ACC",IF(H4<33.34,"RJT","AWR")) -> ACC
C5: b | D5: Specification of material | E5: =100/2 -> 50 | F5: 1 | G5: =E5*F5 -> 50
A7: 2 | B7: Fabrication performance | C7: a | D7: Cutting | E7: =100/4 -> 25 | F7: 1 | G7: =E7*F7 -> 25 | H7: =SUM(G7:G10) -> 100 | I7: =IF(H7>66.67,"ACC",IF(H7<33.34,"RJT","AWR")) -> ACC
C8: b | D8: Holing / Punching / Drilling | E8: =100/4 -> 25 | F8: 1 | G8: =E8*F8 -> 25
C9: c | D9: Bending | E9: =100/4 -> 25 | F9: 1 | G9: =E9*F9 -> 25
C10: d | D10: Welding | E10: =100/4 -> 25 | F10: 1 | G10: =E10*F10 -> 25
A12: 3 | B12: Installation performance | C12: a | D12: Completeness of material | E12: =100/7 -> 14.285714 | F12: 1 | G12: =E12*F12 -> 14.285714 | H12: =SUM(G12:G18) -> 100 | I12: =IF(H12>66.67,"ACC",IF(H12<33.34,"RJT","AWR")) -> ACC
C13: b | D13: Proper connection | E13: =100/7 -> 14.285714 | F13: 1 | G13: =E13*F13 -> 14.285714
C14: c | D14: Torque of bolt / bolt tightness | E14: =100/7 -> 14.285714 | F14: 1 | G14: =E14*F14 -> 14.285714
C15: d | D15: Welding on site | E15: =100/7 -> 14.285714 | F15: 1 | G15: =E15*F15 -> 14.285714
C16: e | D16: Grouting | E16: =100/7 -> 14.285714 | F16: 1 | G16: =E16*F16 -> 14.285714
C17: f | D17: Measurement of installed material | E17: =100/7 -> 14.285714 | F17: 1 | G17: =E17*F17 -> 14.285714
C18: g | D18: Conformance to design | E18: =100/7 -> 14.285714 | F18: 1 | G18: =E18*F18 -> 14.285714
A20: 4 | B20: Galvanizing | C20: a | D20: Thickness of galvanizing | E20: =100/3 -> 33.333333 | F20: 1 | G20: =E20*F20 -> 33.333333 | H20: =SUM(G20:G22) -> 100 | I20: =IF(H20>66.67,"ACC",IF(H20<33.34,"RJT","AWR")) -> ACC
C21: b | D21: Visual test | E21: =100/3 -> 33.333333 | F21: 1 | G21: =E21*F21 -> 33.333333
C22: c | D22: Corrosion | E22: =100/3 -> 33.333333 | F22: 1 | G22: =E22*F22 -> 33.333333
A24: 5 | B24: Finishing works | C24: a | D24: OBL recondition | E24: =100/5 -> 20 | F24: 1 | G24: =E24*F24 -> 20 | H24: =SUM(G24:G28) -> 100 | I24: =IF(H24>66.67,"ACC",IF(H24<33.34,"RJT","AWR")) -> ACC
C25: b | D25: Splitzen recondition | E25: =100/5 -> 20 | F25: 1 | G25: =E25*F25 -> 20
C26: c | D26: Waterprofing paint | E26: =100/5 -> 20 | F26: 1 | G26: =E26*F26 -> 20
C27: d | D27: Painting | E27: =100/5 -> 20 | F27: 1 | G27: =E27*F27 -> 20
C28: e | D28: Cleaness and tidiness of site | E28: =100/5 -> 20 | F28: 1 | G28: =E28*F28 -> 20
A29: CONCLUSION | H29: =SUM(H24,H20,H12,H7,H4) -> 500 | I29: =IF(H29>333.35,"Accepted",IF(H29<166.68,"Rejected","Accepted With Rectification")) -> Accepted
D31: Conclusion | F31: Range
D32: Accepted | F32: > 333.35
D33: Accepted With Rectification | F33: 166.68 < x < 333.34
D34: Rejected | F34: < 166.67
D36: Inspection result | F36: Value
D37: Good | F37: 1
D38: Minor | F38: 0.5
D39: Major | F39: 0

Sheet MASTER
C3: MASTER
C5: Project ID | E5: :
C6: Site Name PO | E6: :
C7: Site Name Tenant | E7: :
C8: Site ID | E8: :
C9: START | E9: : | G9: Tanggal :
C10: DONE | E10: : | G10: Tanggal :
C11: Tenant | E11: :
C12: Type Tower/Heigh | E12: :
C13: Alamat | E13: :
C14: Koordinat | E14: : | F14: Long :
F15: Lat :
C16: Pekerjaan | E16: :
C17: Area | E17: :
C18: Mitra | E18: : | F18: PT. TRITECH CONSULT INDONESIA
C19: ATP Date | E19: :
C21: =F18 -> PT. TRITECH CONSULT INDONESIA
C22: Executive General Manager | E22: :
C23: Manager Construction | E23: :
C25: PT. Dayamitra Telekomunikasi Tbk
C26: GM Area Office Jabodetabeb & Jabar | E26: :
C27: Manager Const Depl TG & OM Area Office Jabodetabeb Inner | E27: :
C28: Project Management | E28: :
C29: Waspang Area | E29: :

Sheet CHECKLIS MK B2S
H1: rev. 03
A3: CHECKLIS BINDER MK B2S
A4: Project ID | C4: : | D4: =MASTER!F5 -> 0
A5: Site Name | C5: : | D5: =MASTER!F7 -> 0
A6: Site ID | C6: : | D6: =MASTER!F8 -> 0
A7: ATP Date | C7: : | D7: =MASTER!F10 -> 0
A9: NO | D9: DESCRIPTION | E9: Doc. Type | F9: CHECK | H9: REMARK
F10: Complete | G10: Not Required
A11: 1 | D11: PLANED DOCUMENT
B12: 1 | D12: Offering / penunjukan Mitra dari procurement | E12: Copy
B13: 2 | D13: Purchase Order | E13: Copy
B14: 3 | D14: Undangan Site Opening + BA Site Opening + Foto Mos | E14: Copy
B15: =B14+1 -> 4 | D15: Undangan pengecoran + BA Pengecoran + Foto Pengecoran | E15: Copy
B16: 5 | D16: RFI Notification + Foto | E16: Copy
B17: =B16+1 -> 6 | D17: Function Test / Foto ATP & Verticality | E17: Copy
B18: 7 | D18: Acceprence Test Dokumen + Closing Pending | E18: Copy
A19: 2 | B19: 8 | D19: SS Oneflux | E19: Copy
A37: Submitted by : | F37: Checked by :
A38: =MASTER!F18 -> PT. TRITECH CONSULT INDONESIA | F38: MITRATEL RO JABODETABEK
A39: Tanggal: | F39: Tanggal:

Sheet EVIDEN
D2: EVIDEN
A4: SITE ID | C4: : | D4: =MASTER!F5 -> 0
A5: SITE NAME | C5: : | D5: =MASTER!F7 -> 0
A6: TENANT | C6: : | D6: ='[40]SKOM '!D6 -> TSEL
A9: EVIDEN

Sheet EVIDEN 1
D2: EVIDEN
A4: SITE ID | C4: : | D4: =MASTER!F5 -> 0
A5: SITE NAME | C5: : | D5: =MASTER!F7 -> 0
A6: TENANT | C6: : | D6: ='[40]SKOM '!D6 -> TSEL
A9: EVIDEN

Sheet EVIDEN 2
D2: EVIDEN
A4: SITE ID | C4: : | D4: =MASTER!F5 -> 0
A5: SITE NAME | C5: : | D5: =MASTER!F7 -> 0
A6: TENANT | C6: : | D6: ='[40]SKOM '!D6 -> TSEL
A9: EVIDEN

Sheet EVIDEN 3
D2: EVIDEN
A4: SITE ID | C4: : | D4: =MASTER!F5 -> 0
A5: SITE NAME | C5: : | D5: =MASTER!F7 -> 0
A6: TENANT | C6: : | D6: ='[40]SKOM '!D6 -> TSEL
A9: EVIDEN

Sheet EVIDEN 4
D2: EVIDEN
A4: SITE ID | C4: : | D4: =MASTER!F5 -> 0
A5: SITE NAME | C5: : | D5: =MASTER!F7 -> 0
A6: TENANT | C6: : | D6: ='[40]SKOM '!D6 -> TSEL
A9: EVIDEN

Sheet EVIDEN 5
D2: EVIDEN
A4: SITE ID | C4: : | D4: =MASTER!F5 -> 0
A5: SITE NAME | C5: : | D5: =MASTER!F7 -> 0
A6: TENANT | C6: : | D6: ='[40]SKOM '!D6 -> TSEL
A9: EVIDEN

Sheet UNDANGAN SKOM

Sheet SKOM
D2: SKOM
A4: SITE ID | C4: : | D4: =MASTER!F5 -> 0
A5: SITE NAME | C5: : | D5: =MASTER!F7 -> 0
A6: TENANT | C6: : | D6: =MASTER!F11 -> 0
A9: MK ON SITE | G9: SKOM
A26: SKOM | G26: SKOM

Sheet PEMBESIAN SITE
D2: DOKUMENTASI PEMBESIAN SITE
A4: SITE ID | C4: : | D4: =SKOM!D4 -> 0
A5: SITE NAME | C5: : | D5: =SKOM!D5 -> 0
A6: TENANT | C6: : | D6: =SKOM!D6 -> 0
A9: PEMBESIAN SITE | G9: PEMBESIAN SITE
A26: PEMBESIAN SITE | G26: PEMBESIAN SITE
A43: PEMBESIAN SITE | G43: PEMBESIAN SITE

Sheet UNDANGAN PENGECORAN

Sheet PENGECORAN SITE
D2: DOKUMENTASI PENGECORAN
A4: SITE ID | C4: : | D4: =SKOM!D4 -> 0
A5: SITE NAME | C5: : | D5: =SKOM!D5 -> 0
A6: TENANT | C6: : | D6: =SKOM!D6 -> 0
A9: MK ON SITE | G9: PERSIAPAN PENGECORAN
A26: PENGECORAN | G26: PENGECORAN
A43: PENGECORAN | G43: PENGECORAN
A58: PENGECORAN | G58: PENGECORAN

Sheet MOS & ERECTION
D2: MOS & ERECTION
A4: SITE ID | C4: : | D4: =SKOM!D4 -> 0
A5: SITE NAME | C5: : | D5: =SKOM!D5 -> 0
A6: TENANT | C6: : | D6: =SKOM!D6 -> 0
A9: MK ON SITE | G9: MATERIAL ON SITE
A26: MATERIAL ON SITE | G26: ERECTION
A42: ERECTION | G42: ERECTION

Sheet UNDANGAN ATP

Sheet PELAKSANAAN ATP
D2: DOKUMENTASI ATP/FUNCTION TEST
A4: SITE ID | C4: : | D4: =SKOM!D4 -> 0
A5: SITE NAME | C5: : | D5: =SKOM!D5 -> 0
A6: TENANT | C6: : | D6: =SKOM!D6 -> 0
A10: FOTO MK | G10: SITE VIEW
A11: `
A27: PANEL ACPDB | G27: PANEL KWH
A28: `
A44: GROUNDING | G44: GROUNDING
A63: PENGUKURAN TEGANGAN RS | G63: PENGUKURAN TEGANGAN RN
A80: PENGUKURAN TEGANGAN RT | G80: PENGUKURAN TEGANGAN SN
A97: PENGUKURAN TEGANGAN ST | G97: PENGUKURAN TEGANGAN TN
A116: PENGUKURAN TEGANGAN NG | G116: PENGUKURAN TEGANGAN
A133: PENGUKURAN TEGANGAN | G133: PENGUKURAN TEGANGAN
A150: PENGUKURAN TEGANGAN | G150: PENGUKURAN TEGANGAN
A167: PENGUKURAN TEGANGAN | G167: PENGUKURAN TEGANGAN
A185: VERTICALITY | G185: VERTICALITY
A202: VERTICALITY | G202: VERTICALITY
